<?xml version="1.0"?>
<robot name="m0609">

  <link name="base_link">
    <inertial>
      <mass value="3.18"/>
      <origin xyz="-2.8e-05 -0.006045 0.038403"/>
      <inertia ixx="0.017789" ixy="-7.4356e-06" ixz="3.0378e-06" iyy="0.011135" iyz="-0.00029038" izz="0.020054"/>
    </inertial>
    <collision>
      <origin rpy="0 0 0" xyz="0 0 0"/>
      <geometry>
        <mesh filename="package://m0609_collision/MF0609_0_0.dae" scale="0.001 0.001 0.001"/>
      </geometry>
    </collision>
    <visual>
      <origin rpy="0 0 0" xyz="0 0 0"/>
      <geometry>
        <mesh filename="package://m0609_white/MF0609_0_0.dae" scale="0.001 0.001 0.001"/>
      </geometry>
    </visual>
  </link>

  <link name="base"/>

  <joint name="base_link-base" type="fixed">
    <origin rpy="0 0 0" xyz="0 0 0.450"/>
    <parent link="base_link"/>
    <child link="base"/>
  </joint>

  <joint name="joint_1" type="revolute">
    <parent link="base_link"/>
    <child link="link_1"/>
    <origin rpy="0 0 0" xyz="0 0 0.1"/>
    <axis xyz="0 0 1"/>
    <limit effort="163" lower="-6.2832" upper="6.2832" velocity="2.618"/>
  </joint>

  <link name="link_1">
    <inertial>
      <mass value="5.02"/>
      <origin xyz="7.2e-05 0.036227 -0.003417"/>
      <inertia ixx="0.026195" ixy="2.3904e-05" ixz="-1.3319e-05" iyy="0.016899" iyz="-0.00071987" izz="0.022944"/>
    </inertial>
    <collision>
      <origin rpy="0 0 0" xyz="0 0 0"/>
      <geometry>
        <mesh filename="package://m0609_collision/MF0609_1_0.dae" scale="0.001 0.001 0.001"/>
      </geometry>
    </collision>
    <visual>
      <origin rpy="0 0 0" xyz="0 0 0"/>
      <geometry>
        <mesh filename="package://m0609_white/MF0609_1_0.dae" scale="0.001 0.001 0.001"/>
      </geometry>
    </visual>
  </link>

  <joint name="joint_2" type="revolute">
    <parent link="link_1"/>
    <child link="link_2"/>
    <origin rpy="0 -1.571 -1.571" xyz="0 0.0062 0"/>
    <axis xyz="0 0 1"/>
    <limit effort="163" lower="-6.2832" upper="6.2832" velocity="2.618"/>
  </joint>

  <link name="link_2">
    <inertial>
      <mass value="8.04"/>
      <origin xyz="0.20447     2.6e-05     0.16005"/>
      <inertia ixx="0.026743" ixy="-0.00019461" ixz="-0.00058734" iyy="0.30084"
        iyz="-6.7892e-06"
        izz="0.29898"/>
    </inertial>
    <collision>
      <origin rpy="0 0 0" xyz="0 0 0" />
      <geometry>
        <mesh filename="package://m0609_collision/MF0609_2_0.dae" scale="0.001 0.001 0.001" />
      </geometry>
    </collision>
    <visual>
      <origin rpy="0 0 0" xyz="0 0 0" />
      <geometry>
        <mesh filename="package://m0609_white/MF0609_2_0.dae" scale="0.001 0.001 0.001" />
      </geometry>
    </visual>
    <collision>
      <origin rpy="0 0 0" xyz="0 0 0" />
      <geometry>
        <mesh filename="package://m0609_collision/MF0609_2_1.dae" scale="0.001 0.001 0.001" />
      </geometry>
    </collision>
    <visual>
      <origin rpy="0 0 0" xyz="0 0 0" />
      <geometry>
        <mesh filename="package://m0609_white/MF0609_2_1.dae" scale="0.001 0.001 0.001" />
      </geometry>
    </visual>
    <collision>
      <origin rpy="0 0 0" xyz="0 0 0" />
      <geometry>
        <mesh filename="package://m0609_collision/MF0609_2_2.dae" scale="0.001 0.001 0.001" />
      </geometry>
    </collision>
    <visual>
      <origin rpy="0 0 0" xyz="0 0 0" />
      <geometry>
        <mesh filename="package://m0609_white/MF0609_2_2.dae" scale="0.001 0.001 0.001" />
      </geometry>
    </visual>
  </link>

  <joint name="joint_3" type="revolute">
    <parent link="link_2"/>
    <child link="link_3"/>
    <origin rpy="0 0 1.571" xyz="0.411 0 0"/>
    <axis xyz="0 0 1"/>
    <limit effort="96" lower="-2.618" upper="2.618" velocity="3.1416"/>
  </joint>

  <link name="link_3">
    <inertial>
      <mass value="3.6"/>
      <origin xyz="-2.2e-05 -0.006867 0.043445"/>
      <inertia ixx="0.018342" ixy="1.1302e-05" ixz="-4.5308e-06" iyy="0.018239" iyz="-0.00099247" izz="0.01326"/>
    </inertial>
    <collision>
      <origin rpy="0 0 0" xyz="0 0 0"/>
      <geometry>
        <mesh filename="package://m0609_collision/MF0609_3_0.dae" scale="0.001 0.001 0.001"/>
      </geometry>
    </collision>
    <visual>
      <origin rpy="0 0 0" xyz="0 0 0"/>
      <geometry>
        <mesh filename="package://m0609_white/MF0609_3_0.dae" scale="0.001 0.001 0.001"/>
      </geometry>
    </visual>
  </link>

  <joint name="joint_4" type="revolute">
    <parent link="link_3"/>
    <child link="link_4"/>
    <origin rpy="1.571 0 0" xyz="0 -0.368 0"/>
    <axis xyz="0 0 1"/>
    <limit effort="50" lower="-6.2832" upper="6.2832" velocity="3.927"/>
  </joint>

  <link name="link_4">
    <inertial>
      <mass value="3.57"/>
      <origin xyz="4e-05    0.097079    -0.10981"/>
      <inertia ixx="0.08035" ixy="-4.6119e-06" ixz="-8.1798e-06" iyy="0.066005"
        iyz="-0.028996"
        izz="0.029763"/>
    </inertial>
    <collision>
      <origin rpy="0 0 0" xyz="0 0 0" />
      <geometry>
        <mesh filename="package://m0609_collision/MF0609_4_0.dae" scale="0.001 0.001 0.001" />
      </geometry>
    </collision>
    <visual>
      <origin rpy="0 0 0" xyz="0 0 0" />
      <geometry>
        <mesh filename="package://m0609_white/MF0609_4_0.dae" scale="0.001 0.001 0.001" />
      </geometry>
    </visual>
    <collision>
      <origin rpy="0 0 0" xyz="0 0 0" />
      <geometry>
        <mesh filename="package://m0609_collision/MF0609_4_1.dae" scale="0.001 0.001 0.001" />
      </geometry>
    </collision>
    <visual>
      <origin rpy="0 0 0" xyz="0 0 0" />
      <geometry>
        <mesh filename="package://m0609_white/MF0609_4_1.dae" scale="0.001 0.001 0.001" />
      </geometry>
    </visual>
  </link>

  <joint name="joint_5" type="revolute">
    <parent link="link_4"/>
    <child link="link_5"/>
    <origin rpy="-1.571 0 0" xyz="0 0 0"/>
    <axis xyz="0 0 1"/>
    <limit effort="50" lower="-6.2832" upper="6.2832" velocity="3.927"/>
  </joint>

  <link name="link_5">
    <inertial>
      <mass value="2.83"/>
      <origin xyz="-6.8e-05 0.003827 0.031969"/>
      <inertia ixx="0.014275" ixy="2.2026e-05" ixz="3.3017e-06" iyy="0.012569" iyz="0.00045077" izz="0.0085318"/>
    </inertial>
    <collision>
      <origin rpy="0 0 0" xyz="0 0 0"/>
      <geometry>
        <mesh filename="package://m0609_collision/MF0609_5_0.dae" scale="0.001 0.001 0.001"/>
      </geometry>
    </collision>
    <visual>
      <origin rpy="0 0 0" xyz="0 0 0"/>
      <geometry>
        <mesh filename="package://m0609_white/MF0609_5_0.dae" scale="0.001 0.001 0.001"/>
      </geometry>
    </visual>
  </link>

  <joint name="joint_6" type="revolute">
    <parent link="link_5"/>
    <child link="link_6"/>
    <origin rpy="1.571 0 0" xyz="0 -0.121 0"/>
    <axis xyz="0 0 1"/>
    <limit effort="50" lower="-6.2832" upper="6.2832" velocity="3.927"/>
  </joint>

  <link name="link_6">
    <inertial>
      <mass value="1.16"/>
      <origin xyz="-3e-05 -4.5e-05 -0.0539"/>
      <inertia ixx="0.0080226" ixy="1.371e-06" ixz="6.3578e-06" iyy="0.0053992" iyz="7.4676e-06" izz="0.0053912"/>
    </inertial>
    <collision>
      <origin rpy="0 0 0" xyz="0 0 0"/>
      <geometry>
        <mesh filename="package://m0609_collision/MF0609_6_0.dae" scale="0.001 0.001 0.001"/>
      </geometry>
    </collision>
    <visual>
      <origin rpy="0 0 0" xyz="0 0 0"/>
      <geometry>
        <mesh filename="package://m0609_white/MF0609_6_0.dae" scale="0.001 0.001 0.001"/>
      </geometry>
    </visual>
  </link>

  <!-- Gripper -->
  <joint name="base_fixed_joint" type="fixed">
    <parent link="link_6"/>
    <child link="hand_link"/>
    <origin xyz="0.000 0.000 0.000" rpy="0 -1.571 0"/>
  </joint>

  <link name="hand_link">
    <collision>
      <origin xyz="0.00 0.00 0.00" rpy="0.00 0.00 0.00"/>
      <geometry>
        <mesh filename="package://rg2_meshes/collision/RG2_Hand_col.STL"/>
      </geometry>
      <surface>
        <contact>
          <lateral_friction value="0.8"/>
          <rolling_friction value="0.5"/>
          <spinning_friction value="0.5"/>
        </contact>
      </surface>
    </collision>
    <visual>
      <origin xyz="0.00 0.00 0.00" rpy="0.00 0.00 0.00"/>
      <geometry>
        <mesh filename="package://rg2_meshes/visual/RG2_Hand_vis.STL"/>
      </geometry>
    </visual>
    <inertial>
      <origin xyz="0.061902 0.000129 -0.000005" rpy="0.00 0.00 0.00"/>
      <mass value="1.684558"/>
      <inertia ixx="0.000862" ixy="0.000000" ixz="0.000000"
              iyy="0.002401" iyz="-0.000001"
              izz="0.002620" />
    </inertial>
  </link>

  <joint name="l_finger_1_joint" type="revolute">
    <parent link="hand_link"/>
    <child link="l_moment_arm_link"/>
    <origin xyz="0.105 0.017 0.010" rpy="0 0 0"/>
    <axis xyz="0 0 1"/>
    <limit velocity="3.14" effort="10.6" lower="-0.45" upper="0.45" />
    <dynamics damping="0.1" friction="0.0" />
  </joint>

  <link name="l_moment_arm_link">
    <collision>
      <origin xyz="0.00 0.00 0.00" rpy="0.00 0.00 0.00"/>
      <geometry>
        <mesh filename="package://rg2_meshes/collision/RG2_LeftMomentArm_col.STL"/>
      </geometry>
      <surface>
        <contact>
          <lateral_friction value="0.8"/>
          <rolling_friction value="0.5"/>
          <spinning_friction value="0.5"/>
        </contact>
      </surface>
    </collision>
    <visual>
      <origin xyz="0.00 0.00 0.00" rpy="0.00 0.00 0.00"/>
      <geometry>
        <mesh filename="package://rg2_meshes/visual/RG2_LeftMomentArm_vis.STL"/>
      </geometry>
    </visual>
    <inertial>
      <origin xyz="0.017004 0.006397 -0.010300" rpy="0.00 0.00 0.00"/>
      <mass value="0.160209"/>
      <inertia ixx="0.000023" ixy="0.000019" ixz="0.000000"
              iyy="0.000072" iyz="0.000000"
              izz="0.000083" />
    </inertial>
  </link>

  <joint name="l_finger_2_joint" type="revolute">
    <parent link="l_moment_arm_link"/>
    <child link="l_finger_link"/>
    <origin xyz="0.049 0.026 0.000" rpy="0 0 0"/>
    <axis xyz="0 0 1"/>
    <limit velocity="3.14" effort="10.6" lower="-0.45" upper="0.45" />
    <dynamics damping="0.1" friction="0.0" />
  </joint>

  <link name="l_finger_link">
    <collision>
      <origin xyz="0.00 0.00 0.00" rpy="0.00 0.00 0.00"/>
      <geometry>
        <mesh filename="package://rg2_meshes/collision/RG2_LeftFinger_col.STL"/>
      </geometry>
      <surface>
        <contact>
          <lateral_friction value="0.8"/>
          <rolling_friction value="0.5"/>
          <spinning_friction value="0.5"/>
        </contact>
      </surface>
    </collision>
    <visual>
      <origin xyz="0.00 0.00 0.00" rpy="0.00 0.00 0.00"/>
      <geometry>
        <mesh filename="package://rg2_meshes/visual/RG2_LeftFinger_vis.STL"/>
      </geometry>
    </visual>
    <inertial>
      <origin xyz="0.024695 -0.010178 -0.010001" rpy="0.00 0.00 0.00"/>
      <mass value="0.081638"/>
      <inertia ixx="0.000006" ixy="-0.000005" ixz="0.000000"
              iyy="0.000025" iyz="0.000000"
              izz="0.000026" />
    </inertial>
  </link>
  
  <joint name="r_finger_1_joint" type="revolute">
    <parent link="hand_link"/>
    <child link="r_moment_arm_link"/>
    <origin xyz="0.105 -0.017 0.010" rpy="0 0 0"/>
    <axis xyz="0 0 1"/>
    <limit velocity="3.14" effort="10.6" lower="-0.45" upper="0.45" />
    <dynamics damping="0.1" friction="0.0" />
  </joint>

  <link name="r_moment_arm_link">
    <collision>
      <origin xyz="0.00 0.00 0.00" rpy="0.00 0.00 0.00"/>
      <geometry>
        <mesh filename="package://rg2_meshes/collision/RG2_RightMomentArm_col.STL"/>
      </geometry>
      <surface>
        <contact>
          <lateral_friction value="0.8"/>
          <rolling_friction value="0.5"/>
          <spinning_friction value="0.5"/>
        </contact>
      </surface>
    </collision>
    <visual>
      <origin xyz="0.00 0.00 0.00" rpy="0.00 0.00 0.00"/>
      <geometry>
        <mesh filename="package://rg2_meshes/visual/RG2_RightMomentArm_vis.STL"/>
      </geometry>
    </visual>
    <inertial>
      <origin xyz="0.017004 -0.006397 -0.010300" rpy="0.00 0.00 0.00"/>
      <mass value="0.160209"/>
      <inertia ixx="0.000023" ixy="-0.000019" ixz="0.000000"
              iyy="0.000072" iyz="0.000000"
              izz="0.000083" />
    </inertial>
  </link>

  <joint name="r_finger_2_joint" type="revolute">
    <parent link="r_moment_arm_link"/>
    <child link="r_finger_link"/>
    <origin xyz="0.049 -0.026 0.000" rpy="0 0 0"/>
    <axis xyz="0 0 1"/>
    <limit velocity="3.14" effort="10.6" lower="-0.45" upper="0.45" />
    <dynamics damping="0.1" friction="0.0" />
  </joint>

  <link name="r_finger_link">
    <collision>
      <origin xyz="0.00 0.00 0.00" rpy="0.00 0.00 0.00"/>
      <geometry>
          <mesh filename="package://rg2_meshes/collision/RG2_RightFinger_col.STL"/>
      </geometry>
      <surface>
        <contact>
          <lateral_friction value="0.8"/>
          <rolling_friction value="0.5"/>
          <spinning_friction value="0.5"/>
        </contact>
      </surface>
    </collision>
    <visual>
      <origin xyz="0.00 0.00 0.00" rpy="0.00 0.00 0.00"/>
      <geometry>
          <mesh filename="package://rg2_meshes/visual/RG2_RightFinger_vis.STL"/>
      </geometry>
    </visual>
    <inertial>
      <origin xyz="0.024695 0.010178 -0.010000" rpy="0.00 0.00 0.00"/>
      <mass value="0.081637"/>
      <inertia ixx="0.000006" ixy="0.000005" ixz="0.000000"
              iyy="0.000025" iyz="0.000000"
              izz="0.000026" />
    </inertial>
  </link>

</robot>
